<?xml version="1.0" encoding="UTF-8"?>
<robot name="demo">

<!-- world link -->
<link name="world"/>

<!-- base_link and its fixed joint -->
<joint name="joint_fix" type="fixed">
  <parent link="world"/>
  <child link="base_link"/>
</joint>

  <link name="base_link">
    <inertial>
      <origin
        xyz="5.43344915757781E-09 0.0443960955613356 1.50000017287721"
        rpy="0 0 0" />
      <mass
        value="17.8923575005348" />
      <inertia
        ixx="0"
        ixy="0"
        ixz="0"
        iyy="0"
        iyz="0"
        izz="0" />
    </inertial>
    <visual>
      <origin
        xyz="0 0 0"
        rpy="0 0 0" />
      <geometry>
        <mesh
          filename="package://demo_test/meshes/base_link.STL" />
      </geometry>
    </visual>
  </link>

  <link name="link1">
    <inertial>
      <origin
        xyz="1.68454688663544E-07 0.164275740780367 -0.0669943121573495"
        rpy="0 0 0" />
      <mass
        value="19.3943177662416" />
      <inertia
        ixx="0"
        ixy="0"
        ixz="0"
        iyy="0"
        iyz="0"
        izz="0" />
    </inertial>
    <visual>
      <origin
        xyz="0 0 0"
        rpy="0 0 0" />
      <geometry>
        <mesh
          filename="package://demo_test/meshes/link1.STL" />
      </geometry>
    </visual>
  </link>

  <joint name="joint1" type="revolute">
    <origin
      xyz="0 0 0.11"
      rpy="1.5707963267949 0 0" />
    <parent
      link="base_link" />
    <child
      link="link1" />
    <axis
      xyz="0 1 0" />
    <limit effort="100" velocity="100" lower="0" upper="3.1416"/>
  </joint>

  <link
    name="link2">
    <inertial>
      <origin
        xyz="0.0328337392440224 0.307142712467886 3.15303338993544E-14"
        rpy="0 0 0" />
      <mass
        value="22.5828591680831" />
      <inertia
        ixx="0"
        ixy="0"
        ixz="0"
        iyy="0"
        iyz="0"
        izz="0" />
    </inertial>
    <visual>
      <origin
        xyz="0 0 0"
        rpy="0 0 0" />
      <geometry>
        <mesh
          filename="package://demo_test/meshes/link2.STL" />
      </geometry>
    </visual>
  </link>

  <joint
    name="joint2"
    type="revolute">
    <origin
      xyz="0 0.322732802998902 -0.250383739680009"
      rpy="0 0 0" />
    <parent
      link="link1" />
    <child
      link="link2" />
    <axis
      xyz="1 0 0" />
    <limit effort="100" velocity="100" lower="0" upper="3.1416"/>
  </joint>

  <link name="link3">
    <inertial>
      <origin
        xyz="0.0261839079462923 2.09127868133763E-05 -0.185012067507171"
        rpy="0 0 0" />
      <mass
        value="13.649633544176" />
      <inertia
        ixx="0"
        ixy="0"
        ixz="0"
        iyy="0"
        iyz="0"
        izz="0" />
    </inertial>
    <visual>
      <origin
        xyz="0 0 0"
        rpy="0 0 0" />
      <geometry>
        <mesh
          filename="package://demo_test/meshes/link3.STL" />
      </geometry>
      <material
        name="">
        <color
          rgba="0.909803921568627 0.443137254901961 0.0313725490196078 1" />
      </material>
    </visual>
  </link>

  <joint
    name="joint3"
    type="revolute">
    <origin
      xyz="0 1.13860941000177 0"
      rpy="0 0 0" />
    <parent
      link="link2" />
    <child
      link="link3" />
    <axis
      xyz="1 0 0" />
    <limit effort="100" velocity="100" lower="0" upper="3.1416"/>
  </joint>

  <link
    name="link5">
    <inertial>
      <origin
        xyz="0 0 0"
        rpy="0 0 0" />
      <mass
        value="0.844952599159698" />
      <inertia
        ixx="0"
        ixy="0"
        ixz="0"
        iyy="0"
        iyz="0"
        izz="0" />
    </inertial>
    <visual>
      <origin
        xyz="0 0 0"
        rpy="0 0 0" />
      <geometry>
        <mesh
          filename="package://demo_test/meshes/link5.STL" />
      </geometry>
    </visual>
  </link>

  <joint
    name="joint5"
    type="continuous">
    <origin
      xyz="0.0483407685108505 0 -0.693420367397096"
      rpy="0 0 0" />
    <parent
      link="link3" />
    <child
      link="link5" />
    <axis
      xyz="0 1 0" />
  </joint>

  <link
    name="link4">
    <inertial>
      <origin
        xyz="0 -1.38777878078145E-17 -0.143700987107576"
        rpy="0 0 0" />
      <mass
        value="3.83524054978555" />
      <inertia
        ixx="0"
        ixy="0"
        ixz="0"
        iyy="0"
        iyz="0"
        izz="0" />
    </inertial>
    <visual>
      <origin
        xyz="0 0 0"
        rpy="0 0 0" />
      <geometry>
        <mesh
          filename="package://demo_test/meshes/link4.STL" />
      </geometry>
    </visual>
  </link>

  <joint
    name="joint4"
    type="revolute">
    <origin
      xyz="0.0383407685108506 0 0"
      rpy="0 0 0" />
    <parent
      link="link5" />
    <child
      link="link4" />
    <axis
      xyz="-1 0 0" />
    <limit effort="100" velocity="100" lower="0" upper="3.1416"/>
  </joint>

  <link name="camera">
    <inertial>
      <origin
        xyz="0 2.22044604925031E-16 -0.0681881207360688"
        rpy="0 0 0" />
      <mass
        value="0.430020999525805" />
      <inertia
        ixx="0"
        ixy="0"
        ixz="0"
        iyy="0"
        iyz="0"
        izz="0" />
    </inertial>
    <visual>
      <origin
        xyz="0 0 0"
        rpy="0 0 0" />
      <geometry>
        <mesh
          filename="package://robot_demo/meshes/camera.STL" />
      </geometry>
    </visual>
  </link>

  <joint
    name="joint_camera"
    type="fixed">
    <origin
      xyz="0 0 -0.18"
      rpy="0 0 0" />
    <parent
      link="link4" />
    <child
      link="camera" />
    <axis
      xyz="0 0 0" />
  </joint>

<!--   <link
    name="base_rot">
    <inertial>
      <origin
        xyz="-8.07968910776367E-17 0.0692439571660551 0"
        rpy="0 0 0" />
      <mass
        value="86.0893233455533" />
      <inertia
        ixx="0"
        ixy="0"
        ixz="0"
        iyy="0"
        iyz="0"
        izz="0" />
    </inertial>
    <visual>
      <origin
        xyz="0 0 0"
        rpy="0 0 0" />
      <geometry>
        <mesh
          filename="package://demo_test/meshes/base_rot.STL" />
      </geometry>
      <material
        name="">
        <color
          rgba="0.792156862745098 0.819607843137255 0.933333333333333 1" />
      </material>
    </visual>
    <collision>
      <origin
        xyz="0 0 0"
        rpy="0 0 0" />
      <geometry>
        <mesh
          filename="package://demo_test/meshes/base_rot.STL" />
      </geometry>
    </collision>
  </link>

  <joint name="joint_p" type="fixed">
    <origin
      xyz="0 1 0"
      rpy="1.5707963267949 0 0" />
    <parent link="world" />
    <child link="base_rot" />
    <axis xyz="0 1 0" />
  </joint>

  <link
    name="plate">
    <inertial>
      <origin
        xyz="-0.00282405785286387 0.909404586795398 -0.00501013645545489"
        rpy="0 0 0" />
      <mass
        value="1357.29950396653" />
      <inertia
        ixx="91.1270275287042"
        ixy="0.299439001894805"
        ixz="-0.00174566238373518"
        iyy="0.00408093994816595"
        iyz="0.531232126869081"
        izz="91.1249145397717" />
    </inertial>
    <visual>
      <origin
        xyz="0 0 0"
        rpy="0 0 0" />
      <geometry>
        <mesh
          filename="package://demo_test/meshes/plate.STL" />
      </geometry>
      <material
        name="">
        <color
          rgba="0 0 0 1" />
      </material>
    </visual>
    <collision>
      <origin
        xyz="0 0 0"
        rpy="0 0 0" />
      <geometry>
        <mesh
          filename="package://demo_test/meshes/plate.STL" />
      </geometry>
    </collision>
  </link>

  <joint
    name="joint5"
    type="revolute">
    <origin
      xyz="0 0.15 0"
      rpy="0 0 0" />
    <parent
      link="base_rot" />
    <child
      link="plate" />
    <axis
      xyz="0 1 0" />
    <limit effort="100" velocity="100" lower="0" upper="3.1416"/>
  </joint> -->

  <gazebo reference="base_link">
    <material>Gazebo/Black</material>
  </gazebo>
  <gazebo reference="link1">
    <material>Gazebo/Orange</material>
  </gazebo>
  <gazebo reference="link2">
    <material>Gazebo/Orange</material>
  </gazebo>
  <gazebo reference="link3">
    <material>Gazebo/Orange</material>
  </gazebo>
  <gazebo reference="link4">
    <material>Gazebo/Red</material>
  </gazebo>

</robot>