<?xml version="1.0" encoding="UTF-8"?>
<robot name="demo">

<!-- world link -->
<link name="world"/>

<!-- base_link and its fixed joint -->
<joint name="joint_fix" type="fixed">
  <parent link="world"/>
  <child link="base_link"/>
</joint>

  <link name="base_link">
    <inertial>
      <origin
        xyz="5.43344915757781E-09 0.0443960955613356 1.50000017287721"
        rpy="0 0 0" />
      <mass
        value="0.1" />
      <inertia
        ixx="0"
        ixy="0"
        ixz="0"
        iyy="0"
        iyz="0"
        izz="0" />
    </inertial>
    <visual>
      <origin
        xyz="0 0 0"
        rpy="0 0 0" />
      <geometry>
        <mesh
          filename="package://demo_test/meshes/base_link.STL" />
      </geometry>
    </visual>
  </link>

  <link name="link1">
    <inertial>
      <origin
        xyz="1.68454688663544E-07 0.164275740780367 -0.0669943121573495"
        rpy="0 0 0" />
      <mass
        value="0.1" />
      <inertia
        ixx="0"
        ixy="0"
        ixz="0"
        iyy="0"
        iyz="0"
        izz="0" />
    </inertial>
    <visual>
      <origin
        xyz="0 0 0"
        rpy="0 0 0" />
      <geometry>
        <mesh
          filename="package://demo_test/meshes/link1.STL" />
      </geometry>
    </visual>
  </link>

  <joint name="joint1" type="revolute">
    <origin
      xyz="0 0 0.11"
      rpy="1.5707963267949 0 0" />
    <parent
      link="base_link" />
    <child
      link="link1" />
    <axis
      xyz="0 1 0" />
    <joint_properties damping="30.0" friction="20.0"/>  
    <limit effort="100" velocity="100" lower="-3.1416" upper="3.1416"/>
  </joint>

  <link
    name="link2">
    <inertial>
      <origin
        xyz="0.0328337392440224 0.307142712467886 3.15303338993544E-14"
        rpy="0 0 0" />
      <mass
        value="5" />
      <inertia
        ixx="0"
        ixy="0"
        ixz="0"
        iyy="0"
        iyz="0"
        izz="0" />
    </inertial>
    <visual>
      <origin
        xyz="0 0 0"
        rpy="0 0 0" />
      <geometry>
        <mesh
          filename="package://demo_test/meshes/link2.STL" />
      </geometry>
    </visual>
  </link>

  <joint
    name="joint2"
    type="revolute">
    <origin
      xyz="0 0.322732802998902 -0.250383739680009"
      rpy="0 0 0" />
    <parent
      link="link1" />
    <child
      link="link2" />
    <axis
      xyz="1 0 0" />
      <joint_properties damping="200.0" friction="150.0"/> 
    <limit effort="100" velocity="100" lower="-3.1416" upper="3.1416"/>
  </joint>

  <link name="link3">
    <inertial>
      <origin
        xyz="0.0261839079462923 2.09127868133763E-05 -0.185012067507171"
        rpy="0 0 0" />
      <mass
        value="0.1" />
      <inertia
        ixx="0"
        ixy="0"
        ixz="0"
        iyy="0"
        iyz="0"
        izz="0" />
    </inertial>
    <visual>
      <origin
        xyz="0 0 0"
        rpy="0 0 0" />
      <geometry>
        <mesh
          filename="package://demo_test/meshes/link3.STL" />
      </geometry>
      <material
        name="">
        <color
          rgba="0.909803921568627 0.443137254901961 0.0313725490196078 1" />
      </material>
    </visual>
  </link>

  <joint
    name="joint3"
    type="revolute">
    <origin
      xyz="0 1.13860941000177 0"
      rpy="0 0 0" />
    <parent
      link="link2" />
    <child
      link="link3" />
    <axis
      xyz="1 0 0" />
      <joint_properties damping="20.0" friction="15.0"/> 
    <limit effort="100" velocity="100" lower="-3.1416" upper="3.1416"/>
  </joint>

  <link
    name="link5">
    <inertial>
      <origin
        xyz="0 0 0"
        rpy="0 0 0" />
      <mass
        value="0.01" />
      <inertia
        ixx="0"
        ixy="0"
        ixz="0"
        iyy="0"
        iyz="0"
        izz="0" />
    </inertial>
    <visual>
      <origin
        xyz="0 0 0"
        rpy="0 0 0" />
      <geometry>
        <mesh
          filename="package://demo_test/meshes/link5.STL" />
      </geometry>
    </visual>
  </link>

  <joint
    name="joint4"
    type="revolute">
    <origin
      xyz="0.0483407685108505 0 -0.693420367397096"
      rpy="0 0 0" />
    <parent
      link="link3" />
    <child
      link="link5" />
    <axis
      xyz="0 1 0" />
      <joint_properties damping="20.0" friction="15.0"/> 
    <limit effort="100" velocity="100" lower="-3.1416" upper="3.1416"/>
  </joint>

  <link
    name="link4">
    <inertial>
      <origin
        xyz="0 -1.38777878078145E-17 -0.143700987107576"
        rpy="0 0 0" />
      <mass
        value="0.001" />
      <inertia
        ixx="0"
        ixy="0"
        ixz="0"
        iyy="0"
        iyz="0"
        izz="0" />
    </inertial>
    <visual>
      <origin
        xyz="0 0 0"
        rpy="0 0 0" />
      <geometry>
        <mesh
          filename="package://demo_test/meshes/link4.STL" />
      </geometry>
    </visual>
  </link>

  <joint
    name="joint5"
    type="revolute">
    <origin
      xyz="0 0 0"
      rpy="0 0 0" />
    <parent
      link="link5" />
    <child
      link="link4" />
    <axis
      xyz="-1 0 0" />
      <joint_properties damping="20.0" friction="15.0"/> 
    <limit effort="100" velocity="100" lower="-3.1416" upper="3.1416"/>
  </joint>

  <link name="camera">
    <inertial>
      <origin
        xyz="0 2.22044604925031E-16 -0.0681881207360688"
        rpy="0 0 0" />
      <mass
        value="0.001" />
      <inertia
        ixx="0"
        ixy="0"
        ixz="0"
        iyy="0"
        iyz="0"
        izz="0" />
    </inertial>
    <visual>
      <origin
        xyz="0 0 0"
        rpy="0 0 0" />
      <geometry>
        <mesh
          filename="package://demo_test/meshes/camera.STL" />
      </geometry>
    </visual>
  </link>

  <joint
    name="joint6"
    type="revolute">
    <origin
      xyz="0 0 -0.18"
      rpy="0 0 0" />
    <parent
      link="link4" />
    <child
      link="camera" />
    <axis
      xyz="0 0 0" />
    <limit effort="100" velocity="100" lower="-3.1416" upper="3.1416"/>
  </joint>

<!-- base_link and its fixed joint -->
<joint name="joint_fix_p" type="fixed">
  <parent link="world"/>
  <child link="base_link_p"/>
</joint>

<link name="base_link_p">
  <collision>
    <origin xyz="0 2.0 0.05" rpy="0 0 0"/>
    <geometry>
      <box size="1 1 0.1"/>
    </geometry>
  </collision>

  <visual>
    <origin xyz="0 2.0 0.05" rpy="0 0 0"/>
    <geometry>
      <box size="1 1 0.1"/>
    </geometry>
  </visual>

  <inertial>
    <origin xyz="0 2.0 0.5" rpy="0 0 0"/>
    <mass value="1"/>
    <inertia
      ixx="1.0" ixy="0.0" ixz="0.0"
      iyy="1.0" iyz="0.0"
      izz="1.0"/>
  </inertial>
</link>

<!-- link1 and its revolute joint1 relative to base_link -->
<!-- rotating along z axis -->
<joint name="joint7" type="revolute">
  <parent link="base_link_p"/>
  <child link="link1_p"/>
  <origin xyz="0 2.0 0.15" rpy="0 0 0"/>
  <axis xyz="0 0 1"/>
  <limit effort="100" velocity="100" lower="-3.1416" upper="3.1416"/>
</joint>

<link name="link1_p">
  <collision>
    <origin xyz="0 0 0" rpy="0 0 0"/>
  <geometry>
    <cylinder length="0.1" radius="0.75"/>
  </geometry>
  </collision>

  <visual>
    <origin xyz="0 0 0" rpy="0 0 0"/>
  <geometry>
    <cylinder length="0.1" radius="0.75"/>
  </geometry>
  </visual>

  <inertial>
    <origin xyz="0 0 0.05" rpy="0 0 0"/>
    <mass value="1"/>
    <inertia
      ixx="1" ixy="0.0" ixz="0.0"
      iyy="1" iyz="0.0"
      izz="1"/>
  </inertial>
</link>

<gazebo reference="link1_p">
  <material>Gazebo/Grey</material>
</gazebo>

<joint name="joint_box" type="fixed">
  <parent link="link1_p"/>
  <child link="box"/>
</joint>

<link name="box">
  <collision>
    <origin xyz="0 0 0.3" rpy="0 0 0"/>
    <geometry>
      <mesh
          filename="package://demo_test/meshes/frig.STL" />
    </geometry>
  </collision>

  <visual>
    <origin xyz="0 0 0" rpy="1.5708 0 0"/>
    <geometry>
      <mesh
          filename="package://demo_test/meshes/frig.STL" />
    </geometry>
  </visual>

  <inertial>
    <origin xyz="0 0 0.05" rpy="0 0 0"/>
    <mass value="1"/>
    <inertia
      ixx="1" ixy="0.0" ixz="0.0"
      iyy="1" iyz="0.0"
      izz="1"/>
  </inertial>
</link>

  <gazebo reference="base_link">
    <material>Gazebo/Black</material>
  </gazebo>
  <gazebo reference="link1">
    <material>Gazebo/Orange</material>
  </gazebo>
  <gazebo reference="link2">
    <material>Gazebo/Orange</material>
  </gazebo>
  <gazebo reference="link3">
    <material>Gazebo/Orange</material>
  </gazebo>
  <gazebo reference="link4">
    <material>Gazebo/Red</material>
  </gazebo>
  <gazebo reference="camera">
    <material>Gazebo/Black</material>
  </gazebo>
  <gazebo reference="box">
    <material>Gazebo/Grey</material>
  </gazebo>

</robot>