<?xml version="1.0" encoding="UTF-8"?>
<robot name="demo_test">

<!-- world link -->
<link name="world"/>

<!-- base_link and its fixed joint -->
<joint name="joint_fix" type="fixed">
  <parent link="world"/>
  <child link="base_link"/>
</joint>

  <link name="base_link">
    <inertial>
      <origin
        xyz="5.43344915355979E-09 0.0443960955613356 1.72877206122885E-07"
        rpy="0 0 0" />
      <mass
        value="17.8923575005348" />
      <inertia
        ixx="0"
        ixy="0"
        ixz="0"
        iyy="0"
        iyz="0"
        izz="0" />
    </inertial>
    <visual>
      <origin
        xyz="0 0 0"
        rpy="0 0 0" />
      <geometry>
        <mesh
          filename="package://demo_test/meshes/base_link.STL" />
      </geometry>
    </visual>
    <collision>
      <origin
        xyz="0 0 0"
        rpy="0 0 0" />
      <geometry>
        <mesh
          filename="package://demo_test/meshes/base_link.STL" />
      </geometry>
    </collision>
  </link>

  <link name="link1">
    <inertial>
      <origin
        xyz="1.68454688765567E-07 0.164275740780367 -0.0669943121573495"
        rpy="0 0 0" />
      <mass
        value="19.3943177662416" />
      <inertia
        ixx="0"
        ixy="0"
        ixz="0"
        iyy="0"
        iyz="0"
        izz="0" />
    </inertial>
    <visual>
      <origin
        xyz="0 0 0"
        rpy="0 0 0" />
      <geometry>
        <mesh
          filename="package://demo_test/meshes/link1.STL" />
      </geometry>
      <material
        name="">
        <color
          rgba="0.780392156862745 0.76078431372549 0.741176470588235 1" />
      </material>
    </visual>
    <collision>
      <origin
        xyz="0 0 0"
        rpy="0 0 0" />
      <geometry>
        <mesh
          filename="package://demo_test/meshes/link1.STL" />
      </geometry>
    </collision>
  </link>

  <joint name="joint1" type="revolute">
    <origin
      xyz="0 -1.5 0.11"
      rpy="1.5707963267949 0 0" />
    <parent
      link="base_link" />
    <child
      link="link1" />
    <axis
      xyz="0 1 0" />
    <limit effort="100" velocity="100" lower="0" upper="3.1416"/>
  </joint>



</robot>