<?xml version="1.0"?>
<robot name="rotation_platform">

<!-- only movable links have number in the name, like link1, link2 -->
<!-- only movable links have number in the name, like joint1, joint2 -->

<!-- world link -->
<link name="world"/>

<!-- base_link and its fixed joint -->
<joint name="joint_fix" type="fixed">
  <parent link="world"/>
  <child link="base_link"/>
</joint>

<link name="base_link">
  <collision>
    <origin xyz="0 0 0.1" rpy="0 0 0"/>
    <geometry>
      <box size="1 1 0.2"/>
    </geometry>
  </collision>

  <visual>
    <origin xyz="0 0 0.1" rpy="0 0 0"/>
    <geometry>
      <box size="1 1 0.2"/>
    </geometry>
  </visual>

  <inertial>
    <origin xyz="0 0 0.5" rpy="0 0 0"/>
    <mass value="1"/>
    <inertia
      ixx="1.0" ixy="0.0" ixz="0.0"
      iyy="1.0" iyz="0.0"
      izz="1.0"/>
  </inertial>
</link>

<!-- link1 and its revolute joint1 relative to base_link -->
<!-- rotating along z axis -->
<joint name="joint1" type="revolute">
  <parent link="base_link"/>
  <child link="link1"/>
  <origin xyz="0 0 0.25" rpy="0 0 0"/>
  <axis xyz="0 0 1"/>
  <limit effort="100" velocity="100" lower="-1.5708" upper="1.5708"/>
</joint>

<link name="link1">
  <collision>
    <origin xyz="0 0 0.1" rpy="0 0 0"/>
    <geometry>
      <box size="1 1 0.2"/>
    </geometry>
  </collision>

<!--   <visual>
    <origin xyz="0 0 0.05" rpy="0 0 0"/>
    <geometry>
      <cylinder length="0.1" radius="1"/>
    </geometry>
  </visual> -->

  <visual>
    <origin xyz="0 0 0.1" rpy="0 0 0"/>
    <geometry>
      <box size="1 1 0.2"/>
    </geometry>
  </visual>

  <inertial>
    <origin xyz="0 0 0.05" rpy="0 0 0"/>
    <mass value="1"/>
    <inertia
      ixx="0.001" ixy="0.0" ixz="0.0"
      iyy="0.001" iyz="0.0"
      izz="0.001"/>
  </inertial>
</link>

<gazebo reference="link1">
  <material>Gazebo/Grey</material>
</gazebo>

